<?xml version="1.0"?>
<!-- TurtleBot3 Waffle Pi -->
<!--
Copied and modified from turtlebot3 example -
https://github.com/ROBOTIS-GIT/turtlebot3/blob/kinetic-devel/turtlebot3_description/urdf/turtlebot3_waffle_pi_for_open_manipulator.urdf.xacro
-->
<robot xmlns:xacro="http://www.ros.org/wiki/xacro">

  <xacro:include filename="$(find realsense2_description)/urdf/_d435.urdf.xacro"/>

  <xacro:macro name="turtlebot3_bigwheel_orin" params="prefix">

    <xacro:property name="meshes_file_direction" value="package://turtlebot3_lime_description/meshes/turtlebot3_bigwheel_orin"/>

    <link name="${prefix}base_footprint"/>

    <joint name="${prefix}base_joint" type="fixed">
      <parent link="${prefix}base_footprint"/>
      <child link="${prefix}base_link" />
      <origin xyz="0 0 0.060" rpy="0 0 0"/>
    </joint>

    <link name="${prefix}base_link">
      <visual>
        <origin xyz="0 0 0" rpy="0 0 0"/>
        <geometry>
          <mesh filename="${meshes_file_direction}/base.stl" scale="0.001 0.001 0.001"/>
        </geometry>
        <material name="light_black"/>
      </visual>

      <collision>
        <origin xyz="-0.065 0 0.0225" rpy="0 0 0"/>
        <geometry>
          <box size="0.266 0.266 0.095"/>
        </geometry>
      </collision>

      <inertial>
        <origin xyz="0 0 0" rpy="0 0 0"/>
        <mass value="1.3729096e+00"/>
        <inertia ixx="8.7002718e-03" ixy="-4.7576583e-05" ixz="1.1160499e-04" iyy="8.6195418e-03" iyz="-3.5422299e-06" izz="1.4612727e-02" />
      </inertial>
    </link>

    <joint name="${prefix}wheel_left_joint" type="continuous">
      <parent link="${prefix}base_link"/>
      <child link="${prefix}wheel_left_link"/>
      <origin xyz="0.0 0.147125 0.0" rpy="-1.57 0 0"/>
      <axis xyz="0 0 1"/>
      <!--XM430-W210-->
      <limit velocity="8.063" effort="3.0"/>
      <dynamics damping="0.7" friction="1.0"/>
    </joint>

    <link name="${prefix}wheel_left_link">
      <visual>
        <origin xyz="0 0 0" rpy="1.57 0 0"/>
        <geometry>
          <mesh filename="${meshes_file_direction}/tire.stl" scale="0.001 0.001 0.001"/>
        </geometry>
        <material name="dark"/>
      </visual>

      <collision>
        <origin xyz="0 0 0" rpy="0 0 0"/>
        <geometry>
          <cylinder length="0.02425" radius="0.06"/>
        </geometry>
      </collision>

      <inertial>
        <origin xyz="0 0 0" />
        <mass value="2.8498940e-02" />
        <inertia ixx="1.1175580e-05" ixy="-4.2369783e-11" ixz="-5.9381719e-09" iyy="1.1192413e-05" iyz="-1.4400107e-11" izz="2.0712558e-05" />
      </inertial>
    </link>

    <joint name="${prefix}wheel_right_joint" type="continuous">
      <parent link="${prefix}base_link"/>
      <child link="${prefix}wheel_right_link"/>
      <origin xyz="0.0 -0.147125 0.0" rpy="-1.57 0 0"/>
      <axis xyz="0 0 1"/>
      <!--XM430-W210-->
      <limit velocity="8.063" effort="3.0"/>
    </joint>

    <link name="${prefix}wheel_right_link">
      <visual>
        <origin xyz="0 0 0" rpy="1.57 0 0"/>
        <geometry>
          <mesh filename="${meshes_file_direction}/tire.stl" scale="0.001 0.001 0.001"/>
        </geometry>
        <material name="dark"/>
      </visual>

      <collision>
        <origin xyz="0 0 0" rpy="0 0 0"/>
        <geometry>
          <cylinder length="0.02425" radius="0.06"/>
        </geometry>
      </collision>

      <inertial>
        <origin xyz="0 0 0" />
        <mass value="2.8498940e-02" />
        <inertia ixx="1.1175580e-05" ixy="-4.2369783e-11" ixz="-5.9381719e-09" iyy="1.1192413e-05" iyz="-1.4400107e-11" izz="2.0712558e-05" />
      </inertial>
    </link>

    <joint name="${prefix}caster_back_right_joint" type="fixed">
      <parent link="${prefix}base_link"/>
      <child link="${prefix}caster_back_right_link"/>
      <origin xyz="-0.176 -0.064 -0.0556125" rpy="-1.57 0 0"/>
    </joint>

    <link name="${prefix}caster_back_right_link">
      <collision>
        <geometry>
          <box size="0.030 0.009 0.005"/>
        </geometry>
      </collision>

      <visual>
        <geometry>
          <sphere radius="0.005"/>
        </geometry>
        <material name="dark"/>
      </visual>

      <inertial>
        <origin xyz="0 0 0" />
        <mass value="0.005" />
        <inertia ixx="0.001" ixy="0.0" ixz="0.0" iyy="0.001" iyz="0.0" izz="0.001" />
      </inertial>
    </link>

    <joint name="${prefix}caster_back_left_joint" type="fixed">
      <parent link="${prefix}base_link"/>
      <child link="${prefix}caster_back_left_link"/>
      <origin xyz="-0.176 0.064 -0.0556125" rpy="-1.57 0 0"/>
    </joint>

    <link name="${prefix}caster_back_left_link">
      <collision>
        <geometry>
          <box size="0.030 0.009 0.005"/>
        </geometry>
      </collision>

      <visual>
        <geometry>
          <sphere radius="0.005"/>
        </geometry>
        <material name="dark"/>
      </visual>

      <inertial>
        <origin xyz="0 0 0" />
        <mass value="0.005" />
        <inertia ixx="0.001" ixy="0.0" ixz="0.0" iyy="0.001" iyz="0.0" izz="0.001" />
      </inertial>
    </link>

    <joint name="${prefix}imu_joint" type="fixed">
      <parent link="${prefix}base_link"/>
      <child link="${prefix}imu_link"/>
      <origin xyz="0.0 0 0.033" rpy="0 0 0"/>
    </joint>

    <link name="${prefix}imu_link"/>

    <joint name="${prefix}scan_joint" type="fixed">
      <parent link="${prefix}base_link"/>
      <child link="${prefix}base_scan"/>
      <origin xyz="0.027 0 0.10045" rpy="0 0 0"/>
    </joint>

    <link name="${prefix}base_scan">
      <visual>
        <origin xyz="0 0 0" rpy="0 0 0"/>
        <geometry>
          <mesh filename="${meshes_file_direction}/ladar.stl" scale="0.001 0.001 0.001"/>
        </geometry>
        <material name="dark"/>
      </visual>

      <collision>
        <origin xyz="0.0 0 -0.0111" rpy="0 0 0"/>
        <geometry>
          <cylinder length="0.0378" radius="0.025"/>
        </geometry>
      </collision>

      <inertial>
        <mass value="0.114" />
        <origin xyz="0 0 0" />
        <inertia ixx="0.001" ixy="0.0" ixz="0.0" iyy="0.001" iyz="0.0" izz="0.001" />
      </inertial>
    </link>

    <joint name="${prefix}battery_joint" type="fixed">
      <parent link="${prefix}base_link"/>
      <child link="${prefix}battery_link"/>
      <origin xyz="-0.08 0 0" rpy="0 0 0"/>
    </joint>

    <link name="${prefix}battery_link">
      <inertial>
        <mass value="1.5" />
        <origin xyz="0 0 0" />
        <inertia ixx="0.001" ixy="0.0" ixz="0.0" iyy="0.001" iyz="0.0" izz="0.001" />
      </inertial>
    </link>

    <xacro:sensor_d435 parent="base_link" use_nominal_extrinsics="true" add_plug="false" use_mesh="true">
      <origin xyz="0.04855 -0.0175 -0.0142" rpy="0 0 0"/>
    </xacro:sensor_d435>

  </xacro:macro>

</robot>
